Workbook

Sheet Overview
A1: HYROX Brisbane 2027 Prep Plan
A3: Race | B3: HYROX Brisbane, Open men
A4: Race window start | B4: 46477
A5: Plan start (Monday, week 1) | B5: 46293 | C5: Edit to shift every week date in Plan
A6: Weeks to race window (from today) | B6: =ROUNDUP((B4-TODAY())/7,0)
A7: Target finish time (h:mm:ss) | B7: 0.059027778 | C7: Your goal; edit anytime
A8: Target heat | B8: Sat Apr 3 or Sun Apr 4 (latest day possible)
A9: Travel | B9: Fly out about Sat Mar 27, land Mon Mar 29 (Brisbane is 14 h ahead)
A10: Tickets (TBA) | B10: https://hyrox.com/event/hyrox-brisbane/
A12: Legend
A13: Yellow cells with blue text = inputs you edit. Everything else is formulas or plan content.
A14: Plan tab: tick Done (Y/N) weekly. Log tab: one row per session. Benchmarks tab: retest in weeks 8, 16, 20.
A16: Race format: 8 x (1 km run + station)
A17: # | B17: Station | C17: Open men | D17: Pro men | E17: Key technique
A18: 1 | B18: SkiErg | C18: 1000 m | D18: 1000 m | E18: Long pulls from hips, steady pace, do not sprint
A19: 2 | B19: Sled push | C19: 50 m, 152 kg incl. sled | D19: 202 kg | E19: Arms locked, low body angle, short fast steps
A20: 3 | B20: Sled pull | C20: 50 m, 103 kg incl. sled | D20: 153 kg | E20: Walk back in the box, hand over hand, use legs
A21: 4 | B21: Burpee broad jumps | C21: 80 m | D21: 80 m | E21: Step up instead of jump up if knee complains; steady rhythm
A22: 5 | B22: Row | C22: 1000 m | D22: 1000 m | E22: Legs first, 24 to 28 spm, do not sprint
A23: 6 | B23: Farmers carry | C23: 200 m, 2 x 24 kg | D23: 2 x 32 kg | E23: Fast walk, no drops
A24: 7 | B24: Sandbag lunges | C24: 100 m, 20 kg | D24: 30 kg | E24: Knee station. Build volume slowly (see Plan)
A25: 8 | B25: Wall balls | C25: 100 reps, 6 kg, 3 m | D25: 9 kg, 3 m | E25: Break early: 25/25/20/15/15, short rests
A26: Confirm weights in the official rulebook when you register.
A29: Phases
A30: Phase | B30: Weeks | C30: Goal | D30: Run km/week | E30: Nutrition
A31: Base | B31: 1 to 8 | C31: Aerobic base, station technique, strength endurance (16 min EMOMs), knee tolerance | D31: 6 to 12 | E31: Eat clean, 150 g protein, no calorie cap
A32: Build 1 | B32: 9 to 14 | C32: Race pace 1 km repeats, 20 min EMOMs at race weights | D32: 10 to 15 | E32: Eat clean, 150 g protein, carbs around runs
A33: Build 2 | B33: 15 to 21 | C33: Running after stations, 24 min EMOMs, first full sims | D33: 11 to 19 | E33: Eat clean, 150 g protein, carbs around sessions
A34: Peak | B34: 22 to 24 | C34: Race pace, EMOMs at race effort, timed dress rehearsal in week 24 | D34: 19 to 20 | E34: Eat to perform, no deficit
A35: Taper | B35: 25 to 26 | C35: Volume down, intensity kept, fly Sat of week 26 | D35: 10 to 14 | E35: Eat to perform, hydrate hard on the flight
A36: Race | B36: 27 | C36: Brisbane: shake out, race Apr 3 or 4 | D36: 6 | E36: Carb up 2 days before
A38: Weekly structure: 4 gym days + hockey, 2 rest days (sessions 60 to 70 min max)
A39: Day | B39: Session
A40: Mon | B40: Heavy lower lift (3 x 5), then a secondary leg lift at RPE 7 (hack squat 3 x 8 in weeks 1 to 8, RDL 3 x 8 in weeks 9 to 21, dropped from week 22), then legs & grip EMOM: sled push, lunges, sled pull, farmers carry
A41: Tue | B41: Run intervals, then arms block A (15 min)
A42: Wed | B42: REST + 12 min mobility routine (daily 3 moves: 4 min)
A43: Thu | B43: Hockey (counts as conditioning)
A44: Fri | B44: Heavy pull + press (3 x 5), then short arms block B (face pulls, cable crunch), then engine EMOM as the finisher (no grip, saves it for Saturday): SkiErg, wall balls, row, burpee broad jumps
A45: Sat | B45: HYROX sim (half most weeks, full in weeks 19, 21, 24)
A46: Sun | B46: REST. From week 9: optional 30 min easy run only if you feel fresh
...

Sheet Plan
A1: Week | B1: Week of | C1: Phase | D1: Focus | E1: MON: Heavy lower + legs & grip EMOM | F1: TUE: Run + arms A | G1: FRI: Heavy upper + arms B + engine EMOM finisher | H1: SAT: HYROX sim | I1: SUN: easy run | J1: Run km target (planned runs only, no warm ups) | K1: Done (Y/N) | L1: Notes
A2: 1 | B2: =Overview!$B$5+7*(A2-1) | C2: Base | D2: Aerobic base, station technique, strength endurance | E2: Trap bar DL 3 x 5 heavy. Hack squat 3 x 8 @ RPE 7. EMOM 16 min (4 rounds), moderate: 1) sled push 20 m 2) 10 lunges/leg bodyweight 3) farmers carry 50 m, 2 x 24 kg 4) rest | F2: 6 x 400 m @ 5k pace, 90 s rest Then arms block A: Lateral raises 4x12-15, incline DB curls 3x10, overhead triceps ext 3x10, hanging leg raises 3x10-12 | G2: Weighted pull ups 3 x 5, DB bench 3 x 8. Then arms block B: Face pulls 3x15, cable crunch 3x10 Finisher: EMOM 16 min: 1) SkiErg 150 m 2) 15 wall balls 3) row 150 m 4) rest | H2: Half sim, race order, half volume, 75%: 4 x (500 m run + stations 1 to 4 at half volume) | I2: Rest | J2: 4.4 | K2: Y
A3: 2 | B3: =Overview!$B$5+7*(A3-1) | C3: Base | D3: Aerobic base, station technique, strength endurance | E3: Trap bar DL 3 x 5 heavy. Hack squat 3 x 8 @ RPE 7. EMOM 16 min (4 rounds), moderate: 1) sled push 20 m 2) 10 lunges/leg bodyweight 3) farmers carry 50 m, 2 x 24 kg 4) rest | F3: 8 x 400 m @ 5k pace, 90 s rest Then arms block A: Lateral raises 4x12-15, incline DB curls 3x10, overhead triceps ext 3x10, hanging leg raises 3x10-12 | G3: Weighted pull ups 3 x 5, DB bench 3 x 8. Then arms block B: Face pulls 3x15, cable crunch 3x10 Finisher: EMOM 16 min: 1) SkiErg 150 m 2) 15 wall balls 3) row 150 m 4) rest | H3: Half sim, 75%: 4 x (500 m run + stations 5 to 8 at half volume) | I3: Rest | J3: 5.2
A4: 3 | B4: =Overview!$B$5+7*(A4-1) | C4: Base | D4: Aerobic base, station technique, strength endurance | E4: Trap bar DL 3 x 5 heavy. Hack squat 3 x 8 @ RPE 7. EMOM 16 min (4 rounds), moderate: 1) sled push 20 m 2) 10 lunges/leg bodyweight 3) farmers carry 50 m, 2 x 24 kg 4) rest | F4: 5 x 600 m, 90 s rest Then arms block A: Lateral raises 4x12-15, incline DB curls 3x10, overhead triceps ext 3x10, hanging leg raises 3x10-12 | G4: Weighted pull ups 3 x 5, DB bench 3 x 8. Then arms block B: Face pulls 3x15, cable crunch 3x10 Finisher: EMOM 16 min: 1) SkiErg 150 m 2) 15 wall balls 3) row 150 m 4) rest | H4: Half sim stations 1 to 4, half volume, 75% | I4: Easy run 30 to 40 min in zone 2: 130 to 140 bpm, full sentences, slow is fine (about 5 km) | J4: 12
A5: 4 | B5: =Overview!$B$5+7*(A5-1) | C5: Base | D5: Deload | E5: Trap bar DL 3 x 5 @ 80%. Hack squat 3 x 8 @ 80%. EMOM 12 min (3 rounds), normal loads: 1) sled push 20 m 2) 10 lunges/leg bodyweight 3) farmers carry 50 m, 2 x 24 kg 4) rest | F5: 4 x 600 m, 90 s rest Then arms block A, 3 sets each: Lateral raises 3x12-15, incline DB curls 3x10, overhead triceps ext 3x10, hanging leg raises 3x10-12 | G5: Weighted pull ups 3 x 5 @ 80%, DB bench 3 x 8 @ 80%. Then arms block B: Face pulls 3x15, Bayesian cable curls 3x10-12, hammer curls 3x10-12, cable crunch 3x10 Finisher: EMOM 12 min: 1) SkiErg 150 m 2) 15 wall balls 3) row 150 m 4) rest | H5: Half sim, 75%, half volume, stations 1 to 4 | I5: Easy run 30 to 40 min in zone 2: 130 to 140 bpm, full sentences, slow is fine (about 5 km) | J5: 11.4
A6: 5 | B6: =Overview!$B$5+7*(A6-1) | C6: Base | D6: Aerobic base, station technique, strength endurance | E6: Trap bar DL 3 x 5 heavy. Hack squat 3 x 8 @ RPE 7. Cable crunch 3x10. EMOM 16 min (4 rounds), moderate: 1) sled push 20 m 2) 10 lunges/leg 10 kg 3) farmers carry 50 m, 2 x 28 kg (above race weight, grip) 4) rest | F6: 4 x 1 km @ 10k pace, 2 min rest Then arms block A: Lateral raises 4x12-15, incline DB curls 4x8-12, overhead triceps ext 3x10, hanging leg raises 3x10-12 | G6: Weighted pull ups 3 x 5, DB bench 3 x 8. Then arms block B: Face pulls 3x15, Bayesian cable curls 3x10-12, hammer curls 3x10-12 Finisher: EMOM 16 min: 1) SkiErg 150 m 2) 15 wall balls 3) row 150 m 4) rest | H6: Half sim, 75%: 4 x (1 km + stations 5 to 8 at half volume) | I6: Easy run 30 to 40 min in zone 2: 130 to 140 bpm, full sentences, slow is fine (about 5 km) | J6: 13
A7: 6 | B7: =Overview!$B$5+7*(A7-1) | C7: Base | D7: Aerobic base, station technique, strength endurance | E7: Trap bar DL 3 x 5 heavy. Hack squat 3 x 8 @ RPE 7. Cable crunch 3x10. EMOM 16 min (4 rounds), moderate: 1) sled push 20 m (last round at race weight) 2) 10 lunges/leg 10 kg 3) farmers carry 50 m, 2 x 28 kg (above race weight, grip) 4) rest | F7: 5 x 1 km @ 10k pace, 2 min rest Then arms block A: Lateral raises 4x12-15, incline DB curls 4x8-12, overhead triceps ext 3x10, hanging leg raises 3x10-12 | G7: Weighted pull ups 3 x 5, DB bench 3 x 8. Then arms block B: Face pulls 3x15, Bayesian cable curls 3x10-12, hammer curls 3x10-12 Wall ball technique 2 x 10. Finisher: EMOM 16 min: 1) SkiErg 150 m 2) 15 wall balls 3) row 150 m 4) rest | H7: Half sim, 75%, half volume, all 8 stations in race order: 8 x (500 m run + station at half volume) | I7: Easy run 30 to 40 min in zone 2: 130 to 140 bpm, full sentences, slow is fine (about 5 km) | J7: 14 | L7: First time through all 8 stations in race order (half volume)
A8: 7 | B8: =Overview!$B$5+7*(A8-1) | C8: Base | D8: Aerobic base, station technique, strength endurance | E8: Trap bar DL 3 x 5 heavy. Hack squat 3 x 8 @ RPE 7. Cable crunch 3x10. EMOM 16 min (4 rounds), moderate: 1) sled push 20 m (last round at race weight) 2) 10 lunges/leg 10 kg 3) farmers carry 50 m, 2 x 28 kg (above race weight, grip) 4) rest | F8: 5 x 1 km @ 10k pace, 90 s rest Then arms block A: Lateral raises 4x12-15, incline DB curls 4x8-12, overhead triceps ext 3x10, hanging leg raises 3x10-12 | G8: Weighted pull ups 3 x 5, DB bench 3 x 8. Then arms block B: Face pulls 3x15, Bayesian cable curls 3x10-12, hammer curls 3x10-12 Wall ball technique 2 x 10. Finisher: EMOM 16 min: 1) SkiErg 150 m 2) 15 wall balls 3) row 150 m 4) rest | H8: Half sim, 75%: 4 x (1 km + stations 5 to 8 at half volume) | I8: Easy run 30 to 40 min in zone 2: 130 to 140 bpm, full sentences, slow is fine (about 5 km) | J8: 14
A9: 8 | B9: =Overview!$B$5+7*(A9-1) | C9: Base | D9: Deload + benchmarks | E9: Trap bar DL 3 x 5 @ 80%. Hack squat 3 x 8 @ 80%. Cable crunch 3x10. EMOM 12 min (3 rounds), normal loads: 1) sled push 20 m 2) 10 lunges/leg 10 kg 3) farmers carry 50 m, 2 x 28 kg (above race weight, grip) 4) rest | F9: 4 x 1 km @ 10k pace, 2 min rest Then arms block A, 3 sets each: Lateral raises 3x12-15, incline DB curls 3x8-12, overhead triceps ext 3x10, hanging leg raises 3x10-12 | G9: Weighted pull ups 3 x 5 @ 80%, DB bench 3 x 8 @ 80%. Then arms block B: Face pulls 3x15, Bayesian cable curls 3x10-12, hammer curls 3x10-12 Wall ball technique 2 x 10. Finisher: EMOM 12 min: 1) SkiErg 150 m 2) 15 wall balls 3) row 150 m 4) rest | H9: Half sim, 75%, half volume, stations 5 to 8 | I9: Easy run 30 to 40 min in zone 2: 130 to 140 bpm, full sentences, slow is fine (about 5 km) | J9: 13 | L9: BENCHMARK WEEK: see Benchmarks tab
A10: 9 | B10: =Overview!$B$5+7*(A10-1) | C10: Build 1 | D10: Race pace running, station endurance at race weights | E10: Back squat 3 x 5. RDL 3 x 8 @ RPE 7. Cable crunch 3x10. EMOM 16 min (4 rounds, shorter: full sim Saturday): 1) sled push 25 m race weight 2) sandbag lunges 20 m, 20 kg 3) farmers 60 m, 2 x 32 kg (above race weight, grip) 4) sled pull 12.5 m race weight | F10: 6 x 1 km @ race pace, 90 s rest Then arms block A: Lateral raises 4x12-15, incline DB curls 4x8-12, overhead triceps ext 3x10, hanging leg raises 3x10-12 | G10: Weighted pull ups 3 x 5, OHP 3 x 5. Then arms block B: Face pulls 3x15, Bayesian cable curls 3x10-12, hammer curls 3x10-12 Wall ball technique 2 x 10. Finisher: EMOM 20 min: 1) SkiErg 200 m 2) 20 wall balls 3) 8 burpee broad jumps 4) row 200 m | H10: FULL SIM at 85%: all 8, record splits | I10: Easy run 30 to 40 min in zone 2: 130 to 140 bpm, full sentences, slow is fine (about 5 km) | J10: 19 | L10: First full sim (moved up from week 19 for Nashville). Full sim again in week 19
A11: 10 | B11: =Overview!$B$5+7*(A11-1) | C11: Build 1 | D11: Race pace running, station endurance at race weights | E11: Back squat 3 x 5. RDL 3 x 8 @ RPE 7. Cable crunch 3x10. EMOM 20 min (5 rounds): 1) sled push 25 m race weight 2) sandbag lunges 20 m, 20 kg 3) farmers 60 m, 2 x 32 kg (above race weight, grip) 4) sled pull 12.5 m race weight | F11: 6 x 1 km @ race pace, 75 s rest Then arms block A: Lateral raises 4x12-15, incline DB curls 4x8-12, overhead triceps ext 3x10, hanging leg raises 3x10-12 | G11: Weighted pull ups 3 x 5, OHP 3 x 5. Then arms block B: Face pulls 3x15, Bayesian cable curls 3x10-12, hammer curls 3x10-12 Wall ball technique 2 x 10. Finisher: EMOM 20 min: 1) SkiErg 200 m 2) 20 wall balls 3) 8 burpee broad jumps 4) row 200 m | H11: Half sim, 75%, half volume: 4 x (500 m run + stations 5 to 8 at half volume). Sharpener before Nashville | I11: Easy run 30 to 40 min in zone 2: 130 to 140 bpm, full sentences, slow is fine (about 5 km) | J11: 13
A12: 11 | B12: =Overview!$B$5+7*(A12-1) | C12: Build 1 | D12: Race pace running, station endurance at race weights | E12: Back squat 3 x 5. RDL 3 x 8 @ RPE 7. Cable crunch 3x10. EMOM 20 min (5 rounds): 1) sled push 25 m race weight 2) sandbag lunges 20 m, 20 kg 3) farmers 60 m, 2 x 32 kg (above race weight, grip) 4) sled pull 12.5 m race weight | F12: 3 x 2 km @ race pace, 2 min rest Then arms block A: Lateral raises 4x12-15, incline DB curls 4x8-12, overhead triceps ext 3x10, hanging leg raises 3x10-12 | G12: Weighted pull ups 3 x 5, OHP 3 x 5. Then arms block B: Face pulls 3x15, Bayesian cable curls 3x10-12, hammer curls 3x10-12 Wall ball technique 2 x 10. Finisher: EMOM 20 min: 1) SkiErg 200 m 2) 20 wall balls 3) 8 burpee broad jumps 4) row 200 m | H12: HYROX Nashville option (Dec 10 or 11, then this Saturday is rest). Else half sim, 80%: 4 x (1 km + stations 1 to 4 full volume) | I12: Optional: easy 20 to 30 min in zone 2, only if fresh after the race | J12: 10 | L12: If racing Nashville: Mon at about 80% loads, Tue 20 min easy, no hockey, the race replaces Fri and Sat
A13: 12 | B13: =Overview!$B$5+7*(A13-1) | C13: Build 1 | D13: Deload | E13: Back squat 3 x 5 @ 80%. RDL 3 x 8 @ 80%. Cable crunch 3x10. EMOM 12 min (3 rounds), normal loads: 1) sled push 25 m race weight 2) sandbag lunges 20 m, 20 kg 3) farmers 60 m, 2 x 32 kg (above race weight, grip) 4) sled pull 12.5 m race weight | F13: 4 x 1 km @ race pace, 2 min rest Then arms block A, 3 sets each: Lateral raises 3x12-15, incline DB curls 3x8-12, overhead triceps ext 3x10, hanging leg raises 3x10-12 | G13: Weighted pull ups 3 x 5 @ 80%, OHP 3 x 5 @ 80%. Then arms block B: Face pulls 3x15, Bayesian cable curls 3x10-12, hammer curls 3x10-12 Wall ball technique 2 x 10. Finisher: EMOM 12 min: 1) SkiErg 200 m 2) 20 wall balls 3) 8 burpee broad jumps 4) row 200 m | H13: Half sim, 75%, half volume, stations 5 to 8 | I13: Easy run 30 to 40 min in zone 2: 130 to 140 bpm, full sentences, slow is fine (about 5 km) | J13: 13
A14: 13 | B14: =Overview!$B$5+7*(A14-1) | C14: Build 1 | D14: Race pace running, station endurance at race weights | E14: Back squat 3 x 5. RDL 3 x 8 @ RPE 7. Cable crunch 3x10. EMOM 20 min (5 rounds): 1) sled push 25 m race weight 2) sandbag lunges 20 m, 20 kg 3) farmers 60 m, 2 x 32 kg (above race weight, grip) 4) sled pull 12.5 m race weight | F14: Holiday week: 5 km tempo Then arms block A: Lateral raises 4x12-15, incline DB curls 4x8-12, overhead triceps ext 3x10, hanging leg raises 3x10-12 | G14: Weighted pull ups 3 x 5, OHP 3 x 5. Then arms block B: Face pulls 3x15, Bayesian cable curls 3x10-12, hammer curls 3x10-12 Wall ball technique 2 x 10. Finisher: EMOM 20 min: 1) SkiErg 200 m 2) 25 wall balls 3) 8 burpee broad jumps 4) row 200 m | H14: Holiday: half sim stations 5 to 8 full volume, 80%, or 30 min EMOM if gym closed | I14: Easy run 30 to 40 min in zone 2: 130 to 140 bpm, full sentences, slow is fine (about 5 km) | J14: 14 | L14: Holidays: keep 3 sessions minimum
A15: 14 | B15: =Overview!$B$5+7*(A15-1) | C15: Build 1 | D15: Race pace running, station endurance at race weights | E15: Back squat 3 x 5. RDL 3 x 8 @ RPE 7. Cable crunch 3x10. EMOM 20 min (5 rounds): 1) sled push 25 m race weight 2) sandbag lunges 20 m, 20 kg 3) farmers 60 m, 2 x 32 kg (above race weight, grip) 4) sled pull 12.5 m race weight | F15: 8 x 1 km @ race pace, 60 s rest Then arms block A: Lateral raises 4x12-15, incline DB curls 4x8-12, overhead triceps ext 3x10, hanging leg raises 3x10-12 | G15: Weighted pull ups 3 x 5, OHP 3 x 5. Then arms block B: Face pulls 3x15, Bayesian cable curls 3x10-12, hammer curls 3x10-12 Wall ball technique 2 x 10. Finisher: EMOM 20 min: 1) SkiErg 200 m 2) 25 wall balls 3) 8 burpee broad jumps 4) row 200 m | H15: Half sim, 80%: 4 x (1 km + stations 1 to 4 full volume) | I15: Easy run 30 to 40 min in zone 2: 130 to 140 bpm, full sentences, slow is fine (about 5 km) | J15: 17
A16: 15 | B16: =Overview!$B$5+7*(A16-1) | C16: Build 2 | D16: Running after stations, long EMOMs, long sims | E16: Back squat 3 x 5. RDL 3 x 8 @ RPE 7. Cable crunch 3x10. EMOM 24 min: 1) sled push 15 m at 110% race weight 2) sandbag lunges 25 m, 25 kg (above race weight) 3) farmers 100 m, 2 x 30 kg (above race weight, grip) 4) sled pull 15 m at 110% race weight | F16: 5 km tempo @ slightly faster than race pace Then arms block A: Lateral raises 4x12-15, incline DB curls 4x8-12, overhead triceps ext 3x10, hanging leg raises 3x10-12 | G16: Weighted pull ups 3 x 5, bench 3 x 5. Then arms block B: Face pulls 3x15, Bayesian cable curls 3x10-12, hammer curls 3x10-12 Wall ball technique 2 x 10. Finisher: EMOM 24 min: 1) SkiErg 250 m 2) 25 wall balls 9 kg (20 lb) 3) 10 burpee broad jumps 4) row 250 m | H16: Half sim, 85%: stations 1 to 4 full volume, 1 km runs at race pace | I16: Easy run 30 to 40 min in zone 2: 130 to 140 bpm, full sentences, slow is fine (about 5 km) | J16: 14
A17: 16 | B17: =Overview!$B$5+7*(A17-1) | C17: Build 2 | D17: Deload + benchmarks | E17: Back squat 3 x 5 @ 80%. RDL 3 x 8 @ 80%. Cable crunch 3x10. EMOM 12 min (3 rounds), normal loads: 1) sled push 15 m at 110% race weight 2) sandbag lunges 25 m, 25 kg (above race weight) 3) farmers 100 m, 2 x 30 kg (above race weight, grip) 4) sled pull 15 m at 110% race weight | F17: 4 x 1 km @ race pace, 90 s rest Then arms block A, 3 sets each: Lateral raises 3x12-15, incline DB curls 3x8-12, overhead triceps ext 3x10, hanging leg raises 3x10-12 | G17: Weighted pull ups 3 x 5 @ 80%, bench 3 x 5 @ 80%. Then arms block B: Face pulls 3x15, Bayesian cable curls 3x10-12, hammer curls 3x10-12 Wall ball technique 2 x 10. Finisher: EMOM 12 min: 1) SkiErg 250 m 2) 25 wall balls 9 kg (20 lb) 3) 10 burpee broad jumps 4) row 250 m | H17: Half sim, 75%, stations 1 to 4 full volume | I17: Easy run 30 to 40 min in zone 2: 130 to 140 bpm, full sentences, slow is fine (about 5 km) | J17: 13 | L17: BENCHMARK WEEK: see Benchmarks tab
A18: 17 | B18: =Overview!$B$5+7*(A18-1) | C18: Build 2 | D18: Running after stations, long EMOMs, long sims | E18: Back squat 3 x 5. RDL 3 x 8 @ RPE 7. Cable crunch 3x10. EMOM 24 min: 1) sled push 15 m at 110% race weight 2) sandbag lunges 25 m, 25 kg (above race weight) 3) farmers 100 m, 2 x 30 kg (above race weight, grip) 4) sled pull 15 m at 110% race weight | F18: 4 x 2 km @ race pace, 90 s rest Then arms block A: Lateral raises 4x12-15, incline DB curls 4x8-12, overhead triceps ext 3x10, hanging leg raises 3x10-12 | G18: Weighted pull ups 3 x 5, bench 3 x 5. Then arms block B: Face pulls 3x15, Bayesian cable curls 3x10-12, hammer curls 3x10-12 Wall ball technique 2 x 10. Finisher: EMOM 24 min: 1) SkiErg 250 m 2) 25 wall balls 9 kg (20 lb) 3) 10 burpee broad jumps 4) row 250 m | H18: Half sim, 85%: stations 5 to 8 full volume, 1 km runs at race pace | I18: Easy run 30 to 40 min in zone 2: 130 to 140 bpm, full sentences, slow is fine (about 5 km) | J18: 17
A19: 18 | B19: =Overview!$B$5+7*(A19-1) | C19: Build 2 | D19: Running after stations, long EMOMs, long sims | E19: Back squat 3 x 5. RDL 3 x 8 @ RPE 7. Cable crunch 3x10. EMOM 24 min: 1) sled push 15 m at 110% race weight 2) sandbag lunges 25 m, 25 kg (above race weight) 3) farmers 100 m, 2 x 30 kg (above race weight, grip) 4) sled pull 15 m at 110% race weight | F19: 6 km tempo Then arms block A: Lateral raises 4x12-15, incline DB curls 4x8-12, overhead triceps ext 3x10, hanging leg raises 3x10-12 | G19: Weighted pull ups 3 x 5, bench 3 x 5. Then arms block B: Face pulls 3x15, Bayesian cable curls 3x10-12, hammer curls 3x10-12 Wall ball technique 2 x 10. Finisher: EMOM 24 min: 1) SkiErg 250 m 2) 25 wall balls 9 kg (20 lb) 3) 10 burpee broad jumps 4) row 250 m | H19: Half sim, 85%: stations 1 to 4, then 2 extra 1 km runs | I19: Easy run 30 to 40 min in zone 2: 130 to 140 bpm, full sentences, slow is fine (about 5 km) | J19: 17
A20: 19 | B20: =Overview!$B$5+7*(A20-1) | C20: Build 2 | D20: Running after stations, long EMOMs, long sims | E20: Back squat 3 x 5. RDL 3 x 8 @ RPE 7. Cable crunch 3x10. EMOM 16 min (shorter: full sim Saturday): 1) sled push 15 m at 110% race weight 2) sandbag lunges 25 m, 25 kg (above race weight) 3) farmers 100 m, 2 x 30 kg (above race weight, grip) 4) sled pull 15 m at 110% race weight | F20: Easy 5 km (full sim Saturday) Then arms block A: Lateral raises 4x12-15, incline DB curls 4x8-12, overhead triceps ext 3x10, hanging leg raises 3x10-12 | G20: Weighted pull ups 3 x 5, bench 3 x 5. Then arms block B: Face pulls 3x15, Bayesian cable curls 3x10-12, hammer curls 3x10-12 Wall ball technique 2 x 10. Finisher: EMOM 16 min (shorter: full sim Saturday): 1) SkiErg 250 m 2) 25 wall balls 9 kg (20 lb) 3) 10 burpee broad jumps 4) row 250 m | H20: FULL SIM at 80%: all 8, record splits | I20: Easy run 30 to 40 min in zone 2: 130 to 140 bpm, full sentences, slow is fine (about 5 km) | J20: 18 | L20: First full sim this week
A21: 20 | B21: =Overview!$B$5+7*(A21-1) | C21: Build 2 | D21: Deload + benchmarks | E21: Back squat 3 x 5 @ 80%. RDL 3 x 8 @ 80%. Cable crunch 3x10. EMOM 12 min (3 rounds), normal loads: 1) sled push 15 m at 110% race weight 2) sandbag lunges 25 m, 25 kg (above race weight) 3) farmers 100 m, 2 x 30 kg (above race weight, grip) 4) sled pull 15 m at 110% race weight | F21: 4 x 1 km @ race pace, 90 s rest Then arms block A, 3 sets each: Lateral raises 3x12-15, incline DB curls 3x8-12, overhead triceps ext 3x10, hanging leg raises 3x10-12 | G21: Weighted pull ups 3 x 5 @ 80%, bench 3 x 5 @ 80%. Then arms block B: Face pulls 3x15, Bayesian cable curls 3x10-12, hammer curls 3x10-12 Wall ball technique 2 x 10. Finisher: EMOM 12 min: 1) SkiErg 250 m 2) 25 wall balls 9 kg (20 lb) 3) 10 burpee broad jumps 4) row 250 m | H21: Half sim, 75%, stations 5 to 8 full volume | I21: Easy run 30 to 40 min in zone 2: 130 to 140 bpm, full sentences, slow is fine (about 5 km) | J21: 13 | L21: BENCHMARK WEEK: see Benchmarks tab
A22: 21 | B22: =Overview!$B$5+7*(A22-1) | C22: Build 2 | D22: Running after stations, long EMOMs, long sims | E22: Back squat 3 x 5. RDL 3 x 8 @ RPE 7. Cable crunch 3x10. EMOM 16 min (shorter: full sim Saturday): 1) sled push 15 m at 110% race weight 2) sandbag lunges 25 m, 25 kg (above race weight) 3) farmers 100 m, 2 x 30 kg (above race weight, grip) 4) sled pull 15 m at 110% race weight | F22: 3 x 3 km @ race pace, 2 min rest Then arms block A: Lateral raises 4x12-15, incline DB curls 4x8-12, overhead triceps ext 3x10, hanging leg raises 3x10-12 | G22: Weighted pull ups 3 x 5, bench 3 x 5. Then arms block B: Face pulls 3x15, Bayesian cable curls 3x10-12, hammer curls 3x10-12 Wall ball technique 2 x 10. Finisher: EMOM 16 min (shorter: full sim Saturday): 1) SkiErg 250 m 2) 25 wall balls 9 kg (20 lb) 3) 10 burpee broad jumps 4) row 250 m | H22: FULL SIM at 90%: all 8, record splits | I22: Easy run 30 to 40 min in zone 2: 130 to 140 bpm, full sentences, slow is fine (about 5 km) | J22: 22
A23: 22 | B23: =Overview!$B$5+7*(A23-1) | C23: Peak | D23: Race specific sharpening | E23: Squat 3 x 3. Cable crunch 3x10. EMOM 20 min at race weight and race effort: 1) sled push 25 m 2) lunges 25 m 3) farmers 100 m 4) sled pull 25 m | F23: 6 x 1 km @ race pace, 60 s rest Then arms block A: Lateral raises 4x12-15, incline DB curls 4x8-12, overhead triceps ext 3x10, hanging leg raises 3x10-12 | G23: Pull ups 3 x 5, press 3 x 5. Then arms block B: Face pulls 3x15, Bayesian cable curls 3x10-12, hammer curls 3x10-12 Finisher: EMOM 20 min at race effort: 1) SkiErg 250 m 2) 25 wall balls 3) 10 burpee broad jumps 4) row 250 m | H23: Half sim at race pace, stations 1 to 4 | I23: Easy run 30 to 40 min in zone 2: 130 to 140 bpm, full sentences, slow is fine (about 5 km) | J23: 15
A24: 23 | B24: =Overview!$B$5+7*(A24-1) | C24: Peak | D24: Race specific sharpening | E24: Squat 3 x 3. Cable crunch 3x10. EMOM 20 min at race weight and race effort: 1) sled push 25 m 2) lunges 25 m 3) farmers 100 m 4) sled pull 25 m | F24: 8 x 1 km @ race pace, 45 s rest Then arms block A: Lateral raises 4x12-15, incline DB curls 4x8-12, overhead triceps ext 3x10, hanging leg raises 3x10-12 | G24: Pull ups 3 x 5, press 3 x 5. Then arms block B: Face pulls 3x15, Bayesian cable curls 3x10-12, hammer curls 3x10-12 Finisher: EMOM 20 min at race effort: 1) SkiErg 250 m 2) 25 wall balls 3) 10 burpee broad jumps 4) row 250 m | H24: Half sim at race pace, stations 5 to 8 | I24: Easy run 30 to 40 min in zone 2: 130 to 140 bpm, full sentences, slow is fine (about 5 km) | J24: 17
A25: 24 | B25: =Overview!$B$5+7*(A25-1) | C25: Peak | D25: Dress rehearsal | E25: Squat 2 x 3 light. EMOM 8 min light: sled push, lunges, farmers, rest | F25: Easy 5 km (dress rehearsal Saturday) Then arms block A: Lateral raises 4x12-15, incline DB curls 4x8-12, overhead triceps ext 3x10, hanging leg raises 3x10-12 | G25: Pull ups 2 x 5. Then arms block B: Face pulls 3x15, Bayesian cable curls 3x10-12, hammer curls 3x10-12, cable crunch 3x10 Finisher: EMOM 8 min light: SkiErg, wall balls, row, rest | H25: FULL RACE SIMULATION: timed, race gear, race breakfast, race pacing | I25: Easy run 30 to 40 min in zone 2: 130 to 140 bpm, full sentences, slow is fine (about 5 km) | J25: 18 | L25: 3 weeks out
A26: 25 | B26: =Overview!$B$5+7*(A26-1) | C26: Taper | D26: Taper: volume down, intensity kept | E26: Squat 2 x 3. EMOM 12 min at race effort, short sets | F26: 5 x 1 km @ race pace, 90 s rest Then arms block A, 2 sets each: Lateral raises 4x12-15, incline DB curls 3x10, overhead triceps ext 3x10, hanging leg raises 3x10-12 | G26: Pull ups 2 x 5. Then arms block B, 2 sets each: Face pulls 3x15, cable crunch 3x10 Finisher: EMOM 12 min at race effort, short sets | H26: Half sim at race pace, stations 1 to 4 at half volume | I26: Easy run 30 min in zone 2: 130 to 140 bpm (taper) | J26: 13
A27: 26 | B27: =Overview!$B$5+7*(A27-1) | C27: Taper | D27: Taper + travel | E27: Squat 2x3 light, sled 2 x 25 m | F27: 4 x 1 km @ race pace Then arms block A, 2 sets each: Lateral raises 4x12-15, incline DB curls 3x10, overhead triceps ext 3x10, hanging leg raises 3x10-12 | G27: Last home session: 20 min easy run + mobility (no arms block) | H27: FLY TO BRISBANE (about Mar 27) | I27: In transit to Brisbane | J27: 4 | L27: No hockey. Shift bedtime 1 h earlier each night from Monday
A28: 27 | B28: =Overview!$B$5+7*(A28-1) | C28: Race | D28: RACE WEEK in Brisbane | E28: Land Mon Mar 29: 20 min easy walk or jog in morning sun, stay up until local night | F28: Brisbane gym: 3 x 1 km @ race pace + light sled and 20 wall balls | G28: Wed: rest. Thu: 15 min shakeout + 4 strides. Fri: rest, carb up | H28: RACE (Sat Apr 3 or Sun Apr 4) | I28: Rest | J28: 11 | L28: No hockey. Race Sunday if you got a Sunday heat
A30: Weeks done | B30: =COUNTIF(K2:K28,"Y")
A31: Completion | B31: =B30/27
A32: K2 shows the format (Y). Clear it if week 1 isn't done yet.

Sheet Log
A1: Date | B1: Week | C1: Session | D1: Run km | E1: Avg 1 km pace (m:ss) | F1: Station notes / times | G1: RPE (1 to 10) | H1: Knee pain (0 to 10) | I1: Notes | K1: Knee pain 4+ turns red. Pace entered as m:ss, e.g. 5:10.
A2: 46293 | B2: =IF(A2="","",INT((A2-Overview!$B$5)/7)+1) | C2: Mon: Lower + EMOM | D2: 0 | F2: EMOM 16 min: sled 20 m, 10 lunges/leg, 15 wall balls. All rounds with 15+ s rest | G2: 7 | H2: 1 | I2: Example row, overwrite
B3: =IF(A3="","",INT((A3-Overview!$B$5)/7)+1)
B4: =IF(A4="","",INT((A4-Overview!$B$5)/7)+1)
B5: =IF(A5="","",INT((A5-Overview!$B$5)/7)+1)
B6: =IF(A6="","",INT((A6-Overview!$B$5)/7)+1)
B7: =IF(A7="","",INT((A7-Overview!$B$5)/7)+1)
B8: =IF(A8="","",INT((A8-Overview!$B$5)/7)+1)
B9: =IF(A9="","",INT((A9-Overview!$B$5)/7)+1)
B10: =IF(A10="","",INT((A10-Overview!$B$5)/7)+1)
B11: =IF(A11="","",INT((A11-Overview!$B$5)/7)+1)
B12: =IF(A12="","",INT((A12-Overview!$B$5)/7)+1)
B13: =IF(A13="","",INT((A13-Overview!$B$5)/7)+1)
B14: =IF(A14="","",INT((A14-Overview!$B$5)/7)+1)
... B200: =IF(A200="","",INT((A200-Overview!$B$5)/7)+1)

Sheet Benchmarks
A1: Test (all times m:ss or h:mm:ss) | B1: Week 1 | C1: Week 8 | D1: Week 16 | E1: Week 20 | F1: Change wk1 to latest | G1: Race target
A2: 1 km run, all out | F2: =IF(COUNT(B2:E2)<2,"",LOOKUP(2,1/(C2:E2<>""),C2:E2)-B2) | G2: 3:45
A3: 5 km run | F3: =IF(COUNT(B3:E3)<2,"",LOOKUP(2,1/(C3:E3<>""),C3:E3)-B3) | G3: 22:30
A4: SkiErg 1000 m | F4: =IF(COUNT(B4:E4)<2,"",LOOKUP(2,1/(C4:E4<>""),C4:E4)-B4) | G4: 4:15
A5: Row 1000 m | F5: =IF(COUNT(B5:E5)<2,"",LOOKUP(2,1/(C5:E5<>""),C5:E5)-B5) | G5: 3:55
A6: 100 wall balls (6 kg) | F6: =IF(COUNT(B6:E6)<2,"",LOOKUP(2,1/(C6:E6<>""),C6:E6)-B6) | G6: 6:00
A7: Sled push 50 m (152 kg) | F7: =IF(COUNT(B7:E7)<2,"",LOOKUP(2,1/(C7:E7<>""),C7:E7)-B7) | G7: 2:30
A8: Farmers carry 200 m (2 x 24 kg) | F8: =IF(COUNT(B8:E8)<2,"",LOOKUP(2,1/(C8:E8<>""),C8:E8)-B8) | G8: 1:45
A9: Sandbag lunges 100 m (20 kg) | F9: =IF(COUNT(B9:E9)<2,"",LOOKUP(2,1/(C9:E9<>""),C9:E9)-B9) | G9: 4:30
A10: Full / half sim time | F10: =IF(COUNT(B10:E10)<2,"",LOOKUP(2,1/(C10:E10<>""),C10:E10)-B10)
A12: Change: negative = faster. Race targets are rough splits for about 1:25 overall; adjust after week 8.
A13: Enter times as m:ss (typed as 0:04:15 in Excel).
